package gregicadditions.jei.multi.simple;

import gregicadditions.item.CellCasing;
import gregicadditions.item.GAMetaBlocks;
import gregicadditions.item.GATransparentCasing;
import gregicadditions.item.metal.MetalCasing1;
import gregicadditions.item.metal.MetalCasing2;
import gregicadditions.jei.GAMultiblockShapeInfo;
import gregicadditions.machines.GATileEntities;
import gregtech.api.metatileentity.multiblock.MultiblockControllerBase;
import gregtech.common.blocks.BlockMultiblockCasing;
import gregtech.common.blocks.MetaBlocks;
import gregtech.common.metatileentities.MetaTileEntities;
import gregtech.integration.jei.multiblock.MultiblockInfoPage;
import gregtech.integration.jei.multiblock.MultiblockShapeInfo;
import net.minecraft.client.resources.I18n;
import net.minecraft.init.Blocks;
import net.minecraft.util.EnumFacing;

import java.util.ArrayList;
import java.util.List;

import static gregtech.api.multiblock.BlockPattern.RelativeDirection.*;

public class BlackHoleGeneratorInfo extends MultiblockInfoPage {

    @Override
    public MultiblockControllerBase getController() {
    return GATileEntities.BLACK_HOLE;
}

    @Override
    public List<MultiblockShapeInfo> getMatchingShapes() {
        List<MultiblockShapeInfo> shapeInfos = new ArrayList<>();
        GAMultiblockShapeInfo.Builder builder = GAMultiblockShapeInfo.builder()
                .aisle("                                ", "                                ", "                                ", "                                ", "                                ", "                                ", "                                ", "                                ", "                                ", "                                ", "                                ", "                                ", "                                ", "                                ", "                                ", "                                ", "                                ", "                                ", "                                ", "                                ", "                                ", "                                ", "                                ", "                                ", "                                ", "                                ", "                                ", "                                ", "                                ", "                                ", "                                ", "                                ", "                                ", "                                ", "                                ", "                                ", "                                ", "                                ", "                                ", "                                ", "                                ", "                                ", "                                ", "                                ", "                                ")
                .aisle("                                ", "                                ", "                                ", "                                ", "                                ", "                                ", "                                ", "                                ", "                                ", "                                ", "                                ", "                                ", "                                ", "                                ", "                                ", "                                ", "                                ", "                                ", "                                ", "                                ", "                                ", "                                ", "                                ", "                                ", "                                ", "                                ", "                                ", "                                ", "                                ", "                                ", "                                ", "                                ", "                                ", "                                ", "                                ", "                                ", "                                ", "                                ", "                                ", "                                ", "                                ", "                                ", "                                ", "                                ", "                                ")
                .aisle("            CCCCCCC             ", "                                ", "                                ", "                                ", "                                ", "                                ", "                                ", "                                ", "                                ", "                                ", "                                ", "                                ", "                                ", "                                ", "                                ", "                                ", "                                ", "                                ", "                                ", "                                ", "                                ", "                                ", "                                ", "                                ", "                                ", "                                ", "                                ", "              DDD               ", "             DDDDD              ", "            DDDDDDD             ", "            DDDDDDD             ", "            DDDDDDD             ", "             DDDDD              ", "              DDD               ", "                                ", "                                ", "                                ", "                                ", "                                ", "                                ", "                                ", "                                ", "                                ", "                                ", "                                ")
                .aisle("         CCCCCCCCCCCCC          ", "                                ", "                                ", "                                ", "                                ", "                                ", "                                ", "                                ", "                                ", "                                ", "                                ", "                                ", "                                ", "                                ", "                                ", "                                ", "                                ", "                                ", "                                ", "                                ", "                                ", "                                ", "                                ", "                                ", "              DDD               ", "            DDDDDDD             ", "           DDDDDDDDD            ", "          DDDD   DDDD           ", "          DDD     DDD           ", "         DDD       DDD          ", "         DDD       DDD          ", "         DDD       DDD          ", "          DDD     DDD           ", "          DDDD   DDDD           ", "           DDDDDDDDD            ", "            DDDDDDD             ", "              DDD               ", "                                ", "                                ", "                                ", "                                ", "                                ", "                                ", "                                ", "                                ")
                .aisle("        CCCCCCCCCCCCCCC         ", "                                ", "                                ", "                                ", "                                ", "                                ", "                                ", "                                ", "                                ", "                                ", "                                ", "                                ", "                                ", "                                ", "                                ", "                                ", "                                ", "                                ", "                                ", "                                ", "                                ", "                                ", "                                ", "            DDDDDDD             ", "          DDDDDDDDDDD           ", "         DDD       DDD          ", "         DD         DD          ", "        DD           DD         ", "        DD           DD         ", "        DD           DD         ", "        DD           DD         ", "        DD           DD         ", "        DD           DD         ", "        DD           DD         ", "         DD         DD          ", "         DDD       DDD          ", "          DDDDDDDDDDD           ", "            DDDDDDD             ", "                                ", "                                ", "                                ", "                                ", "                                ", "                                ", "                                ")
                .aisle("      CCCCCCCCCCCCCCCCCCC       ", "                                ", "                                ", "                                ", "                                ", "                                ", "                                ", "                                ", "                                ", "                                ", "                                ", "                                ", "                                ", "                                ", "                                ", "                                ", "                                ", "                                ", "                                ", "                                ", "                                ", "             DDDDD              ", "           DDDDDDDDD            ", "         DDD       DDD          ", "        DDD         DDD         ", "        DD           DD         ", "       DD             DD        ", "       D               D        ", "      DD               DD       ", "      DD               DD       ", "      DD               DD       ", "      DD               DD       ", "      DD               DD       ", "       D               D        ", "       DD             DD        ", "        DD           DD         ", "        DDD         DDD         ", "         DDD       DDD          ", "           DDDDDDDDD            ", "             DDDDD              ", "                                ", "                                ", "                                ", "                                ", "                                ")
                .aisle("     CCCCCCCCCCCCCCCCCCCCC      ", "                                ", "                                ", "                                ", "                                ", "                                ", "                                ", "                                ", "                                ", "                                ", "                                ", "                                ", "                                ", "                                ", "                                ", "                                ", "                                ", "                                ", "                                ", "                                ", "             DDDDD              ", "          DDDDDDDDDDD           ", "         DDD       DDD          ", "        DD           DD         ", "       DD             DD        ", "      DD               DD       ", "      DD               DD       ", "      D                 D       ", "     DD                 DD      ", "     DD                 DD      ", "     DD                 DD      ", "     DD                 DD      ", "     DD                 DD      ", "      D                 D       ", "      DD               DD       ", "      DD               DD       ", "       DD             DD        ", "        DD           DD         ", "         DDD       DDD          ", "          DDDDDDDDDDD           ", "             DDDDD              ", "                                ", "                                ", "                                ", "                                ")
                .aisle("    CCCCCCCCCCCCCCCCCCCCCCC     ", "                                ", "                                ", "                                ", "                                ", "                                ", "                                ", "                                ", "                                ", "                                ", "                                ", "                                ", "                                ", "                                ", "                                ", "                                ", "                                ", "                                ", "                                ", "             DDDDD              ", "          DDDDDDDDDDD           ", "         DD         DD          ", "        DD           DD         ", "       D               D        ", "      DD               DD       ", "     DD                 DD      ", "     D                   D      ", "     D                   D      ", "    DD                   DD     ", "    DD                   DD     ", "    DD                   DD     ", "    DD                   DD     ", "    DD                   DD     ", "     D                   D      ", "     D                   D      ", "     DD                 DD      ", "      DD               DD       ", "       D               D        ", "        DD           DD         ", "         DD         DD          ", "          DDDDDDDDDDD           ", "             DDDDD              ", "                                ", "                                ", "                                ")
                .aisle("    CCCCCCCCCCCCCCCCCCCCCCC     ", "                                ", "                                ", "                                ", "                                ", "                                ", "                                ", "                                ", "                                ", "                                ", "                                ", "                                ", "                                ", "                                ", "                                ", "                                ", "                                ", "                                ", "                                ", "           DDDDDDDDD            ", "         DDD       DDD          ", "        DD           DD         ", "       D               D        ", "      D                 D       ", "     DD                 DD      ", "     D                   D      ", "    DD                   DD     ", "    D                     D     ", "    D                     D     ", "    D                     D     ", "    D                     D     ", "    D                     D     ", "    D                     D     ", "    D                     D     ", "    DD                   DD     ", "     D                   D      ", "     DD                 DD      ", "      D                 D       ", "       D               D        ", "        DD           DD         ", "         DDD       DDD          ", "           DDDDDDDDD            ", "                                ", "                                ", "                                ")
                .aisle("   CCCCCCCCCCCCCCCCCCCCCCCCC    ", "                                ", "                                ", "                                ", "                                ", "                                ", "                                ", "                                ", "                                ", "                                ", "                                ", "                                ", "                                ", "                                ", "                                ", "                                ", "                                ", "                                ", "            DDDDDDD             ", "         DDD       DDD          ", "        DD           DD         ", "       D               D        ", "      D                 D       ", "     D                   D      ", "    DD                   DD     ", "    D                     D     ", "    D                     D     ", "   D                       D    ", "   D                       D    ", "   D                       D    ", "   D                       D    ", "   D                       D    ", "   D                       D    ", "   D                       D    ", "    D                     D     ", "    D                     D     ", "    DD                   DD     ", "     D                   D      ", "      D                 D       ", "       D               D        ", "        DD           DD         ", "         DDD       DDD          ", "            DDDDDDD             ", "                                ", "                                ")
                .aisle("  CCCCCCCCCCCCCCCCCCCCCCCCCCC   ", "                                ", "                                ", "                                ", "                                ", "                                ", "                                ", "                                ", "                                ", "                                ", "                                ", "                                ", "                                ", "                                ", "                                ", "                                ", "                                ", "              DDD               ", "          DDDDDDDDDDD           ", "        DDD         DDD         ", "       DD             DD        ", "      DD               DD       ", "     DD                 DD      ", "    DD                   DD     ", "    D                     D     ", "   DD                     DD    ", "   D                       D    ", "   D                       D    ", "   D                       D    ", "  DD                       DD   ", "  DD                       DD   ", "  DD                       DD   ", "   D                       D    ", "   D                       D    ", "   D                       D    ", "   DD                     DD    ", "    D                     D     ", "    DD                   DD     ", "     DD                 DD      ", "      DD               DD       ", "       DD             DD        ", "        DDD         DDD         ", "          DDDDDDDDDDD           ", "              DDD               ", "                                ")
                .aisle("  CCCCCCCCCCCCCCCCCCCCCCCCCCC   ", "                                ", "               E                ", "              HTJ               ", "              EEE               ", "              EEE               ", "              EEE               ", "              EEE               ", "              EEE               ", "              EEE               ", "              EEE               ", "               E                ", "               E                ", "                                ", "                                ", "                                ", "                                ", "            DDDDDDD             ", "         DDD       DDD          ", "        DD           DD         ", "      DD               DD       ", "     DD                 DD      ", "     D                   D      ", "    D                     D     ", "   DD                     DD    ", "   D                       D    ", "   D                       D    ", "  D                         D   ", "  D                         D   ", "  D                         D   ", "  D                         D   ", "  D                         D   ", "  D                         D   ", "  D                         D   ", "   D                       D    ", "   D                       D    ", "   DD                     DD    ", "    D                     D     ", "     D                   D      ", "     DD                 DD      ", "      DD               DD       ", "        DD           DD         ", "         DDD       DDD          ", "            DDDDDDD             ", "                                ")
                .aisle("  CCCCCCCCCCCCCCCCCCCCCCCCCCC   ", "               E                ", "              E E               ", "              E E               ", "              E E               ", "              E E               ", "              E E               ", "              E E               ", "              E E               ", "              E E               ", "              E E               ", "              E E               ", "              EEE               ", "                                ", "                                ", "                                ", "                                ", "           DDDDDDDDD            ", "         DD         DD          ", "       DD             DD        ", "      DD               DD       ", "     D                   D      ", "    DD                   DD     ", "    D                     D     ", "   D                       D    ", "   D                       D    ", "  D                         D   ", "  D                         D   ", "  D                         D   ", "  D                         D   ", "  D                         D   ", "  D                         D   ", "  D                         D   ", "  D                         D   ", "  D                         D   ", "   D                       D    ", "   D                       D    ", "    D                     D     ", "    DD                   DD     ", "     D                   D      ", "      DD               DD       ", "       DD             DD        ", "         DD         DD          ", "           DDDDDDDDD            ", "                                ")
                .aisle(" CCCCCCCCCCCCCCCCCCCCCCCCCCCCC  ", "              E E               ", "             E   E              ", "             E   E              ", "             E   E              ", "             E   E              ", "             E   E              ", "             E   E              ", "             E   E              ", "             E   E              ", "             E   E              ", "             E   E              ", "             EE EE              ", "               E                ", "                                ", "                                ", "              DDD               ", "          DDDD   DDDD           ", "        DD           DD         ", "       D               D        ", "      D                 D       ", "     D                   D      ", "    D                     D     ", "   D                       D    ", "   D                       D    ", "  D                         D   ", "  D                         D   ", "  D                         D   ", "  D                         D   ", " DD                          D  ", " DD                          D  ", " DD                          D  ", "  D                         D   ", "  D                         D   ", "  D                         D   ", "  D                         D   ", "   D                       D    ", "   D                       D    ", "    D                     D     ", "     D                   D      ", "      D                 D       ", "       D               D        ", "        DD           DD         ", "          DDDD   DDDD           ", "              DDD               ")
                .aisle(" CCCCCCCCCCCCCCCCCCCCCCCCCCCCC  ", "             E   E              ", "            E     E             ", "            E     E             ", "            E     E             ", "            E     E             ", "            E     E             ", "            E     E             ", "            E     E             ", "            E     E             ", "            E     E             ", "            E     E             ", "            EE   EE             ", "              E E               ", "               E                ", "                                ", "             DDDDD              ", "          DDD     DDD           ", "        DD           DD         ", "      DD               DD       ", "     DD                 DD      ", "    DD                   DD     ", "    D                     D     ", "   D                       D    ", "   D                       D    ", "  D                         D   ", "  D                         D   ", "  D                         D   ", " D                           D  ", " D                           D  ", " D                           D  ", " D                           D  ", " D                           D  ", "  D                         D   ", "  D                         D   ", "  D                         D   ", "   D                       D    ", "   D                       D    ", "    D                     D     ", "    DD                   DD     ", "     DD                 DD      ", "      DD               DD       ", "        DD           DD         ", "          DDD     DDD           ", "             DDDDD              ")
                .aisle(" CCCCCCCCCCCCCCCCCCCCCCCCCCCCC  ", "            E     E             ", "           E       E            ", "          IE       EU           ", "          EE       EE           ", "          EE       EE           ", "          EE       EE           ", "          EE       EE           ", "          EE       EE           ", "          EE       EE           ", "          EE       EE           ", "           E       E            ", "           EE     EE            ", "             E   E              ", "              EEE               ", "                                ", "            DDDDDDD             ", "         DDD       DDD          ", "        DD           DD         ", "      DD               DD       ", "     DD                 DD      ", "    DD                   DD     ", "    D                     D     ", "   D                       D    ", "  DD                       DD   ", "  D                         D   ", "  D                         D   ", " D                           D  ", " D                           D  ", " D                           D  ", " D                           D  ", " D                           D  ", " D                           D  ", " D                           D  ", "  D                         D   ", "  D                         D   ", "  DD                       DD   ", "   D                       D    ", "    D                     D     ", "    DD                   DD     ", "     DD                 DD      ", "      DD               DD       ", "        DD           DD         ", "         DDD       DDD          ", "            DDDDDDD             ")
                .aisle(" CCCCCCCCCCCCCCCCCCCCCCCCCCCCC  ", "           E       E            ", "          E         E           ", "          G         F           ", "          E         E           ", "          E         E           ", "          E         E           ", "          E         E           ", "          E         E           ", "          E         E           ", "          E         E           ", "          E         E           ", "          EE       EE           ", "            E     E             ", "             EEEEE              ", "                                ", "            DDDDDDD             ", "         DDD       DDD          ", "        DD           DD         ", "      DD               DD       ", "     DD                 DD      ", "    DD                   DD     ", "    D                     D     ", "   D                       D    ", "  DD                       DD   ", "  D                         D   ", "  D                         D   ", " D                           D  ", " D                           D  ", " D                           D  ", " D                           D  ", " D                           D  ", " D                           D  ", " D                           D  ", "  D                         D   ", "  D                         D   ", "  DD                       DD   ", "   D                       D    ", "    D                     D     ", "    DD                   DD     ", "     DD                 DD      ", "      DD               DD       ", "        DD           DD         ", "         DDD       DDD          ", "            DDDDDDD             ")
                .aisle(" CCCCCCCCCCCCCCCCCCCCCCCCCCCCC  ", "            E     E             ", "           E       E            ", "          KE       EF           ", "          EE       EE           ", "          EE       EE           ", "          EE       EE           ", "          EE       EE           ", "          EE       EE           ", "          EE       EE           ", "          EE       EE           ", "           E       E            ", "           EE     EE            ", "             E   E              ", "              EEE               ", "                                ", "            DDDDDDD             ", "         DDD       DDD          ", "        DD           DD         ", "      DD               DD       ", "     DD                 DD      ", "    DD                   DD     ", "    D                     D     ", "   D                       D    ", "  DD                       DD   ", "  D                         D   ", "  D                         D   ", " D                           D  ", " D                           D  ", " D                           D  ", " D                           D  ", " D                           D  ", " D                           D  ", " D                           D  ", "  D                         D   ", "  D                         D   ", "  DD                       DD   ", "   D                       D    ", "    D                     D     ", "    DD                   DD     ", "     DD                 DD      ", "      DD               DD       ", "        DD           DD         ", "         DDD       DDD          ", "            DDDDDDD             ")
                .aisle(" CCCCCCCCCCCCCCCCCCCCCCCCCCCCC  ", "             E   E              ", "            E     E             ", "            E     E             ", "            E     E             ", "            E     E             ", "            E     E             ", "            E     E             ", "            E     E             ", "            E     E             ", "            E     E             ", "            E     E             ", "            E     E             ", "             EE EE              ", "               E                ", "                                ", "             DDDDD              ", "          DDD     DDD           ", "        DD           DD         ", "      DD               DD       ", "     DD                 DD      ", "    DD                   DD     ", "    D                     D     ", "   D                       D    ", "   D                       D    ", "  D                         D   ", "  D                         D   ", "  D                         D   ", " D                           D  ", " D                           D  ", " D                           D  ", " D                           D  ", " D                           D  ", "  D                         D   ", "  D                         D   ", "  D                         D   ", "   D                       D    ", "   D                       D    ", "    D                     D     ", "    DD                   DD     ", "     DD                 DD      ", "      DD               DD       ", "        DD           DD         ", "          DDD     DDD           ", "             DDDDD              ")
                .aisle(" CCCCCCCCCCCCCCCCCCCCCCCCCCCCC  ", "              E E               ", "             E   E              ", "             E   E              ", "             E   E              ", "             E   E              ", "             E   E              ", "             E   E              ", "             E   E              ", "             E   E              ", "             E   E              ", "             E   E              ", "             EE EE              ", "               E                ", "                                ", "                                ", "              DDD               ", "          DDDD   DDDD           ", "        DD           DD         ", "       D               D        ", "      D                 D       ", "     D                   D      ", "    D                     D     ", "   D                       D    ", "   D                       D    ", "  D                         D   ", "  D                         D   ", "  D                         D   ", "  D                         D   ", " D                           D  ", " D                           D  ", " D                           D  ", "  D                         D   ", "  D                         D   ", "  D                         D   ", "  D                         D   ", "   D                       D    ", "   D                       D    ", "    D                     D     ", "     D                   D      ", "      D                 D       ", "       D               D        ", "        DD           DD         ", "          DDDD   DDDD           ", "              DDD               ")
                .aisle("  CCCCCCCCCCCCCCCCCCCCCCCCCCC   ", "               E                ", "              E E               ", "              E E               ", "              E E               ", "              E E               ", "              E E               ", "              E E               ", "              E E               ", "              E E               ", "              E E               ", "              E E               ", "              EEE               ", "                                ", "                                ", "                                ", "                                ", "           DDDDDDDDD            ", "         DD         DD          ", "       DD             DD        ", "      DD               DD       ", "     D                   D      ", "    DD                   DD     ", "    D                     D     ", "   D                       D    ", "   D                       D    ", "  D                         D   ", "  D                         D   ", "  D                         D   ", "  D                         D   ", "  D                         D   ", "  D                         D   ", "  D                         D   ", "  D                         D   ", "  D                         D   ", "   D                       D    ", "   D                       D    ", "    D                     D     ", "    DD                   DD     ", "     D                   D      ", "      DD               DD       ", "       DD             DD        ", "         DD         DD          ", "           DDDDDDDDD            ", "                                ")
                .aisle("  CCCCCCCCCCCCCCCCCCCCCCCCCCC   ", "                                ", "               E                ", "              FFF               ", "              EEE               ", "              EEE               ", "              EEE               ", "              EEE               ", "              EEE               ", "              EEE               ", "              EEE               ", "               E                ", "               E                ", "                                ", "                                ", "                                ", "                                ", "            DDDDDDD             ", "         DDD       DDD          ", "        DD           DD         ", "      DD               DD       ", "     DD                 DD      ", "     D                   D      ", "    D                     D     ", "   DD                     DD    ", "   D                       D    ", "   D                       D    ", "  D                         D   ", "  D                         D   ", "  D                         D   ", "  D                         D   ", "  D                         D   ", "  D                         D   ", "  D                         D   ", "   D                       D    ", "   D                       D    ", "   DD                     DD    ", "    D                     D     ", "     D                   D      ", "     DD                 DD      ", "      DD               DD       ", "        DD           DD         ", "         DDD       DDD          ", "            DDDDDDD             ", "                                ")
                .aisle("  CCCCCCCCCCCCCCCCCCCCCCCCCCC   ", "                                ", "                                ", "                                ", "                                ", "                                ", "                                ", "                                ", "                                ", "                                ", "                                ", "                                ", "                                ", "                                ", "                                ", "                                ", "                                ", "              DDD               ", "          DDDDDDDDDDD           ", "        DDD         DDD         ", "       DD             DD        ", "      DD               DD       ", "     DD                 DD      ", "    DD                   DD     ", "    D                     D     ", "   DD                     DD    ", "   D                       D    ", "   D                       D    ", "   D                       D    ", "  DD                       DD   ", "  DD                       DD   ", "  DD                       DD   ", "   D                       D    ", "   D                       D    ", "   D                       D    ", "   DD                     DD    ", "    D                     D     ", "    DD                   DD     ", "     DD                 DD      ", "      DD               DD       ", "       DD             DD        ", "        DDD         DDD         ", "          DDDDDDDDDDD           ", "              DDD               ", "                                ")
                .aisle("   CCCCCCCCCCCCCCCCCCCCCCCCC    ", "                                ", "                                ", "                                ", "                                ", "                                ", "                                ", "                                ", "                                ", "                                ", "                                ", "                                ", "                                ", "                                ", "                                ", "                                ", "                                ", "                                ", "            DDDDDDD             ", "         DDD       DDD          ", "        DD           DD         ", "       D               D        ", "      D                 D       ", "     D                   D      ", "    DD                   DD     ", "    D                     D     ", "    D                     D     ", "   D                       D    ", "   D                       D    ", "   D                       D    ", "   D                       D    ", "   D                       D    ", "   D                       D    ", "   D                       D    ", "    D                     D     ", "    D                     D     ", "    DD                   DD     ", "     D                   D      ", "      D                 D       ", "       D               D        ", "        DD           DD         ", "         DDD       DDD          ", "            DDDDDDD             ", "                                ", "                                ")
                .aisle("    CCCCCCCCCCCCCCCCCCCCCCC     ", "                                ", "                                ", "                                ", "                                ", "                                ", "                                ", "                                ", "                                ", "                                ", "                                ", "                                ", "                                ", "                                ", "                                ", "             AAAAA              ", "                                ", "                                ", "                                ", "           DDDDDDDDD            ", "         DDD       DDD          ", "        DD           DD         ", "       D               D        ", "      D                 D       ", "     DD                 DD      ", "     D                   D      ", "    DD                   DD     ", "    D                     D     ", "    D                     D     ", "    D                     D     ", "    D                     D     ", "    D                     D     ", "    D                     D     ", "    D                     D     ", "    DD                   DD     ", "     D                   D      ", "     DD                 DD      ", "      D                 D       ", "       D               D        ", "        DD           DD         ", "         DDD       DDD          ", "           DDDDDDDDD            ", "                                ", "                                ", "                                ")
                .aisle("    CCCCCCCCCCCCCCCCCCCCCCC     ", "             AAAAA              ", "             AAAAA              ", "                                ", "                                ", "                                ", "                                ", "                                ", "                                ", "                                ", "                                ", "                                ", "                                ", "                                ", "                                ", "                                ", "             AAAAA              ", "                                ", "                                ", "             DDDDD              ", "          DDDDDDDDDDD           ", "         DD         DD          ", "        DD           DD         ", "       D               D        ", "      DD               DD       ", "     DD                 DD      ", "     D                   D      ", "     D                   D      ", "    DD                   DD     ", "    DD                   DD     ", "    DD                   DD     ", "    DD                   DD     ", "    DD                   DD     ", "     D                   D      ", "     D                   D      ", "     DD                 DD      ", "      DD               DD       ", "       D               D        ", "        DD           DD         ", "         DD         DD          ", "          DDDDDDDDDDD           ", "             DDDDD              ", "                                ", "                                ", "                                ")
                .aisle("     CCCCCCCCCCCCCCCCCCCCC      ", "             AAAAA              ", "             A   A              ", "             AAAAA              ", "                                ", "                                ", "                                ", "                                ", "                                ", "                                ", "                                ", "                                ", "                                ", "                                ", "                                ", "                                ", "                                ", "             AAAAA              ", "                                ", "                                ", "             DDDDD              ", "          DDDDDDDDDDD           ", "         DDD       DDD          ", "        DD           DD         ", "       DD             DD        ", "      DD               D        ", "      DD               DD       ", "      D                 D       ", "      D                 DD      ", "      D                 DD      ", "     DD                 DD      ", "     DD                 DD      ", "     DD                 DD      ", "      D                 D       ", "      DD               DD       ", "      DD               DD       ", "       DD             DD        ", "        DD           DD         ", "         DDD       DDD          ", "          DDDDDDDDDDD           ", "             DDDDD              ", "                                ", "                                ", "                                ", "                                ")
                .aisle("      CCCCCCCCCCCCCCCCCCC       ", "             AAAAA              ", "             A   A              ", "             A   A              ", "             AAAAA              ", "                                ", "                                ", "                                ", "                                ", "                                ", "                                ", "                                ", "                                ", "                                ", "                                ", "                                ", "             AAAAA              ", "                                ", "                                ", "                                ", "                                ", "             DDDDD              ", "           DDDDDDDDD            ", "         DDD       DDD          ", "        DDD         DDD         ", "        DD           DD         ", "       DD             DD        ", "       D               D        ", "      DD               DD       ", "      DD               DD       ", "      DD               DD       ", "      DD               DD       ", "      DD               DD       ", "       D               D        ", "       DD             DD        ", "        DD           DD         ", "        DDD         DDD         ", "         DDD       DDD          ", "           DDDDDDDDD            ", "             DDDDD              ", "                                ", "                                ", "                                ", "                                ", "                                ")
                .aisle("        CCCCCCCCCCCCCCC         ", "             AAAAA              ", "             A   A              ", "             A   A              ", "             AAAAA              ", "             AAAAA              ", "                                ", "                                ", "                                ", "                                ", "                                ", "                                ", "                                ", "                                ", "                                ", "             AAAAA              ", "             A   A              ", "             AAAAA              ", "                                ", "             AAAAA              ", "                                ", "                                ", "                                ", "            DDDDDDD             ", "          DDDDDDDDDDD           ", "         DDD       DDD          ", "         DD         DD          ", "        DD           DD         ", "        DD           DD         ", "        DD           DD         ", "        DD           DD         ", "        DD           DD         ", "        DD           DD         ", "        DD           DD         ", "         DD         DD          ", "         DDD       DDD          ", "          DDDDDDDDDDD           ", "            DDDDDDD             ", "                                ", "                                ", "                                ", "                                ", "                                ", "                                ", "                                ")
                .aisle("         CCCCCCCCCCCCC          ", "             AAAAA              ", "             A   A              ", "             A   A              ", "             A   A              ", "             A   A              ", "             AAAAA              ", "                                ", "                                ", "                                ", "                                ", "                                ", "                                ", "                                ", "             AAAAA              ", "             A   A              ", "             A   A              ", "             A   A              ", "             AAAAA              ", "                                ", "             AAAAA              ", "                                ", "                                ", "                                ", "              DDD               ", "            DDDDDDD             ", "           DDDDDDDDD            ", "          DDDD   DDDD           ", "          DDD     DDD           ", "         DDD       DDD          ", "         DDD       DDD          ", "         DDD       DDD          ", "          DDD     DDD           ", "          DDDD   DDDD           ", "           DDDDDDDDD            ", "            DDDDDDD             ", "              DDD               ", "                                ", "                                ", "                                ", "                                ", "                                ", "                                ", "                                ", "                                ")
                .aisle("            CCCCCCC             ", "             AAAAA              ", "             A   A              ", "             A   A              ", "             A   A              ", "             A   A              ", "             AAAAA              ", "                                ", "                                ", "                                ", "                                ", "                                ", "                                ", "             AAAAA              ", "             A   A              ", "             A   A              ", "             A   A              ", "             AAAAA              ", "                                ", "                                ", "                                ", "             AAAAA              ", "                                ", "                                ", "                                ", "                                ", "                                ", "              DDD               ", "             DDDDD              ", "            DDDDDDD             ", "            DDDDDDD             ", "            DDDDDDD             ", "             DDDDD              ", "              DDD               ", "                                ", "                                ", "                                ", "                                ", "                                ", "                                ", "                                ", "                                ", "                                ", "                                ", "                                ")
                .aisle("                                ", "                                ", "             AAAAA              ", "             AAAAA              ", "             A   A              ", "             A   A              ", "             A   A              ", "             AAAAA              ", "                                ", "                                ", "                                ", "                                ", "             AAAAA              ", "             A   A              ", "             A   A              ", "             A   A              ", "             AAAAA              ", "                                ", "                                ", "                                ", "                                ", "                                ", "                                ", "                                ", "                                ", "                                ", "                                ", "                                ", "                                ", "                                ", "                                ", "                                ", "                                ", "                                ", "                                ", "                                ", "                                ", "                                ", "                                ", "                                ", "                                ", "                                ", "                                ", "                                ", "                                ")
                .aisle("                                ", "                                ", "                                ", "             AAAAA              ", "             AAAAA              ", "             A   A              ", "             A   A              ", "             A   A              ", "             AAAAA              ", "             AAAAA              ", "             AAAAA              ", "             AAAAA              ", "             A   A              ", "             A   A              ", "             A   A              ", "             AAAAA              ", "                                ", "                                ", "                                ", "                                ", "                                ", "                                ", "                                ", "                                ", "                                ", "                                ", "                                ", "                                ", "                                ", "                                ", "                                ", "                                ", "                                ", "                                ", "                                ", "                                ", "                                ", "                                ", "                                ", "                                ", "                                ", "                                ", "                                ", "                                ", "                                ")
                .aisle("                                ", "                                ", "                                ", "                                ", "                                ", "             AAAAA              ", "             A   A              ", "             A   A              ", "             A   A              ", "             A   A              ", "             A   A              ", "             A   A              ", "             A   A              ", "             A   A              ", "             AAAAA              ", "                                ", "                                ", "                                ", "                                ", "                                ", "                                ", "                                ", "                                ", "                                ", "                                ", "                                ", "                                ", "                                ", "                                ", "                                ", "                                ", "                                ", "                                ", "                                ", "                                ", "                                ", "                                ", "                                ", "                                ", "                                ", "                                ", "                                ", "                                ", "                                ", "                                ")
                .aisle("                                ", "                                ", "                                ", "                                ", "                                ", "                                ", "             AAAAA              ", "             AAAAA              ", "             A   A              ", "             A   A              ", "             A   A              ", "             A   A              ", "             AAAAA              ", "             AAAAA              ", "                                ", "                                ", "                                ", "                                ", "                                ", "                                ", "                                ", "                                ", "                                ", "                                ", "                                ", "                                ", "                                ", "                                ", "                                ", "                                ", "                                ", "                                ", "                                ", "                                ", "                                ", "                                ", "                                ", "                                ", "                                ", "                                ", "                                ", "                                ", "                                ", "                                ", "                                ")
                .aisle("                                ", "                                ", "                                ", "                                ", "                                ", "                                ", "                                ", "             AAAAA              ", "             AAAAA              ", "             A   A              ", "             A   A              ", "             AAAAA              ", "             AAAAA              ", "                                ", "                                ", "                                ", "                                ", "                                ", "                                ", "                                ", "                                ", "                                ", "                                ", "                                ", "                                ", "                                ", "                                ", "                                ", "                                ", "                                ", "                                ", "                                ", "                                ", "                                ", "                                ", "                                ", "                                ", "                                ", "                                ", "                                ", "                                ", "                                ", "                                ", "                                ", "                                ")
                .aisle("                                ", "                                ", "                                ", "                                ", "                                ", "                                ", "                                ", "                                ", "                                ", "             AAAAA              ", "             AAAAA              ", "                                ", "                                ", "                                ", "                                ", "                                ", "                                ", "                                ", "                                ", "                                ", "                                ", "                                ", "                                ", "                                ", "                                ", "                                ", "                                ", "                                ", "                                ", "                                ", "                                ", "                                ", "                                ", "                                ", "                                ", "                                ", "                                ", "                                ", "                                ", "                                ", "                                ", "                                ", "                                ", "                                ", "                                ")
                .where('G', GATileEntities.BLACK_HOLE, EnumFacing.WEST)
                .where('U', GATileEntities.MAINTENANCE_HATCH[2], EnumFacing.EAST)
                .where('C', (GAMetaBlocks.METAL_CASING_1.getState(MetalCasing1.CasingType.HASTELLOY_X78)))
                .where('E', (MetaBlocks.MUTLIBLOCK_CASING.getState(BlockMultiblockCasing.MultiblockCasingType.FUSION_CASING)))
                .where('F', (MetaBlocks.MUTLIBLOCK_CASING.getState(BlockMultiblockCasing.MultiblockCasingType.FUSION_CASING)))
                .where('D',(GAMetaBlocks.TRANSPARENT_CASING.getState(GATransparentCasing.CasingType.OSMIRIDIUM_GLASS)))
                .where('A', (GAMetaBlocks.METAL_CASING_2.getState(MetalCasing2.CasingType.TRITANIUM)));
        for (int tier = 0; tier < 15; tier++) {
            shapeInfos.add(builder.where('H', GATileEntities.getEnergyHatch(Math.min(14, tier), true), EnumFacing.NORTH)
                    .where('I', MetaTileEntities.FLUID_IMPORT_HATCH[Math.min(9, tier)], EnumFacing.WEST)
                    .where('T', MetaTileEntities.FLUID_EXPORT_HATCH[Math.min(9, tier)], EnumFacing.NORTH)
                    .where('K', MetaTileEntities.ITEM_IMPORT_BUS[Math.min(9, tier)], EnumFacing.WEST)
                    .where('J', MetaTileEntities.ITEM_EXPORT_BUS[Math.min(9, tier)], EnumFacing.NORTH)
                    .build());
        }
        return shapeInfos;
    }

@Override
    public String[] getDescription() {
        return new String[]{I18n.format("gtadditions.multiblock.battery_tower.description")};
    }

    @Override
    public float getDefaultZoom() {
        return 0.2f;
    }
}
